[2022-11-26T09:29:09.315+0000] {taskinstance.py:1165} INFO - Dependencies all met for <TaskInstance: data_ingestion_s3_dag.upload_to_s3 manual__2022-11-26T09:23:56.491966+00:00 [queued]>
[2022-11-26T09:29:09.322+0000] {taskinstance.py:1165} INFO - Dependencies all met for <TaskInstance: data_ingestion_s3_dag.upload_to_s3 manual__2022-11-26T09:23:56.491966+00:00 [queued]>
[2022-11-26T09:29:09.323+0000] {taskinstance.py:1362} INFO - 
--------------------------------------------------------------------------------
[2022-11-26T09:29:09.324+0000] {taskinstance.py:1363} INFO - Starting attempt 1 of 2
[2022-11-26T09:29:09.325+0000] {taskinstance.py:1364} INFO - 
--------------------------------------------------------------------------------
[2022-11-26T09:29:09.332+0000] {taskinstance.py:1383} INFO - Executing <Task(PythonOperator): upload_to_s3> on 2022-11-26 09:23:56.491966+00:00
[2022-11-26T09:29:09.337+0000] {standard_task_runner.py:55} INFO - Started process 488 to run task
[2022-11-26T09:29:09.341+0000] {standard_task_runner.py:82} INFO - Running: ['***', 'tasks', 'run', 'data_ingestion_s3_dag', 'upload_to_s3', 'manual__2022-11-26T09:23:56.491966+00:00', '--job-id', '97', '--raw', '--subdir', 'DAGS_FOLDER/data_ingestion_s3_dag.py', '--cfg-path', '/tmp/tmp2ec9f7yt']
[2022-11-26T09:29:09.343+0000] {standard_task_runner.py:83} INFO - Job 97: Subtask upload_to_s3
[2022-11-26T09:29:09.390+0000] {task_command.py:376} INFO - Running <TaskInstance: data_ingestion_s3_dag.upload_to_s3 manual__2022-11-26T09:23:56.491966+00:00 [running]> on host 7d1b5368210b
[2022-11-26T09:29:09.438+0000] {taskinstance.py:1592} INFO - Exporting the following env vars:
AIRFLOW_CTX_DAG_OWNER=***
AIRFLOW_CTX_DAG_ID=data_ingestion_s3_dag
AIRFLOW_CTX_TASK_ID=upload_to_s3
AIRFLOW_CTX_EXECUTION_DATE=2022-11-26T09:23:56.491966+00:00
AIRFLOW_CTX_TRY_NUMBER=1
AIRFLOW_CTX_DAG_RUN_ID=manual__2022-11-26T09:23:56.491966+00:00
[2022-11-26T09:29:09.465+0000] {base_aws.py:120} INFO - No connection ID provided. Fallback on boto3 credential strategy (region_name=None). See: https://boto3.amazonaws.com/v1/documentation/api/latest/guide/configuration.html
[2022-11-26T09:29:09.485+0000] {credentials.py:1180} INFO - Found credentials in environment variables.
[2022-11-26T09:29:11.111+0000] {taskinstance.py:1851} ERROR - Task failed with exception
Traceback (most recent call last):
  File "/home/airflow/.local/lib/python3.7/site-packages/boto3/s3/transfer.py", line 288, in upload_file
    future.result()
  File "/home/airflow/.local/lib/python3.7/site-packages/s3transfer/futures.py", line 103, in result
    return self._coordinator.result()
  File "/home/airflow/.local/lib/python3.7/site-packages/s3transfer/futures.py", line 266, in result
    raise self._exception
  File "/home/airflow/.local/lib/python3.7/site-packages/s3transfer/tasks.py", line 139, in __call__
    return self._execute_main(kwargs)
  File "/home/airflow/.local/lib/python3.7/site-packages/s3transfer/tasks.py", line 162, in _execute_main
    return_value = self._main(**kwargs)
  File "/home/airflow/.local/lib/python3.7/site-packages/s3transfer/upload.py", line 758, in _main
    client.put_object(Bucket=bucket, Key=key, Body=body, **extra_args)
  File "/home/airflow/.local/lib/python3.7/site-packages/botocore/client.py", line 515, in _api_call
    return self._make_api_call(operation_name, kwargs)
  File "/home/airflow/.local/lib/python3.7/site-packages/botocore/client.py", line 934, in _make_api_call
    raise error_class(parsed_response, operation_name)
botocore.errorfactory.NoSuchBucket: An error occurred (NoSuchBucket) when calling the PutObject operation: The specified bucket does not exist

During handling of the above exception, another exception occurred:

Traceback (most recent call last):
  File "/home/airflow/.local/lib/python3.7/site-packages/airflow/operators/python.py", line 175, in execute
    return_value = self.execute_callable()
  File "/home/airflow/.local/lib/python3.7/site-packages/airflow/operators/python.py", line 193, in execute_callable
    return self.python_callable(*self.op_args, **self.op_kwargs)
  File "/opt/airflow/dags/data_ingestion_s3_dag.py", line 38, in upload_to_s3
    hook.load_file(filename=filename, key=key, bucket_name=bucket_name)
  File "/home/airflow/.local/lib/python3.7/site-packages/airflow/providers/amazon/aws/hooks/s3.py", line 64, in wrapper
    return func(*bound_args.args, **bound_args.kwargs)
  File "/home/airflow/.local/lib/python3.7/site-packages/airflow/providers/amazon/aws/hooks/s3.py", line 92, in wrapper
    return func(*bound_args.args, **bound_args.kwargs)
  File "/home/airflow/.local/lib/python3.7/site-packages/airflow/providers/amazon/aws/hooks/s3.py", line 649, in load_file
    client.upload_file(filename, bucket_name, key, ExtraArgs=extra_args, Config=self.transfer_config)
  File "/home/airflow/.local/lib/python3.7/site-packages/boto3/s3/inject.py", line 148, in upload_file
    callback=Callback,
  File "/home/airflow/.local/lib/python3.7/site-packages/boto3/s3/transfer.py", line 296, in upload_file
    filename, '/'.join([bucket, key]), e
boto3.exceptions.S3UploadFailedError: Failed to upload /opt/***/yellow_tripdata_2021-01.csv to s3_bucket_1/new_york_data: An error occurred (NoSuchBucket) when calling the PutObject operation: The specified bucket does not exist
[2022-11-26T09:29:11.141+0000] {taskinstance.py:1406} INFO - Marking task as UP_FOR_RETRY. dag_id=data_ingestion_s3_dag, task_id=upload_to_s3, execution_date=20221126T092356, start_date=20221126T092909, end_date=20221126T092911
[2022-11-26T09:29:11.162+0000] {standard_task_runner.py:105} ERROR - Failed to execute job 97 for task upload_to_s3 (Failed to upload /opt/***/yellow_tripdata_2021-01.csv to s3_bucket_1/new_york_data: An error occurred (NoSuchBucket) when calling the PutObject operation: The specified bucket does not exist; 488)
[2022-11-26T09:29:11.187+0000] {local_task_job.py:159} INFO - Task exited with return code 1
[2022-11-26T09:29:11.199+0000] {taskinstance.py:2623} INFO - 0 downstream tasks scheduled from follow-on schedule check
