[2022-11-26T09:34:12.346+0000] {taskinstance.py:1165} INFO - Dependencies all met for <TaskInstance: data_ingestion_s3_dag.upload_to_s3 manual__2022-11-26T09:23:56.491966+00:00 [queued]>
[2022-11-26T09:34:12.356+0000] {taskinstance.py:1165} INFO - Dependencies all met for <TaskInstance: data_ingestion_s3_dag.upload_to_s3 manual__2022-11-26T09:23:56.491966+00:00 [queued]>
[2022-11-26T09:34:12.358+0000] {taskinstance.py:1362} INFO - 
--------------------------------------------------------------------------------
[2022-11-26T09:34:12.358+0000] {taskinstance.py:1363} INFO - Starting attempt 2 of 2
[2022-11-26T09:34:12.359+0000] {taskinstance.py:1364} INFO - 
--------------------------------------------------------------------------------
[2022-11-26T09:34:12.368+0000] {taskinstance.py:1383} INFO - Executing <Task(PythonOperator): upload_to_s3> on 2022-11-26 09:23:56.491966+00:00
[2022-11-26T09:34:12.372+0000] {standard_task_runner.py:55} INFO - Started process 747 to run task
[2022-11-26T09:34:12.375+0000] {standard_task_runner.py:82} INFO - Running: ['***', 'tasks', 'run', 'data_ingestion_s3_dag', 'upload_to_s3', 'manual__2022-11-26T09:23:56.491966+00:00', '--job-id', '98', '--raw', '--subdir', 'DAGS_FOLDER/data_ingestion_s3_dag.py', '--cfg-path', '/tmp/tmpplvx39ud']
[2022-11-26T09:34:12.378+0000] {standard_task_runner.py:83} INFO - Job 98: Subtask upload_to_s3
[2022-11-26T09:34:12.417+0000] {task_command.py:376} INFO - Running <TaskInstance: data_ingestion_s3_dag.upload_to_s3 manual__2022-11-26T09:23:56.491966+00:00 [running]> on host 7d1b5368210b
[2022-11-26T09:34:12.459+0000] {taskinstance.py:1592} INFO - Exporting the following env vars:
AIRFLOW_CTX_DAG_OWNER=***
AIRFLOW_CTX_DAG_ID=data_ingestion_s3_dag
AIRFLOW_CTX_TASK_ID=upload_to_s3
AIRFLOW_CTX_EXECUTION_DATE=2022-11-26T09:23:56.491966+00:00
AIRFLOW_CTX_TRY_NUMBER=2
AIRFLOW_CTX_DAG_RUN_ID=manual__2022-11-26T09:23:56.491966+00:00
[2022-11-26T09:34:12.468+0000] {base_aws.py:120} INFO - No connection ID provided. Fallback on boto3 credential strategy (region_name=None). See: https://boto3.amazonaws.com/v1/documentation/api/latest/guide/configuration.html
[2022-11-26T09:34:12.477+0000] {credentials.py:1180} INFO - Found credentials in environment variables.
[2022-11-26T09:34:16.399+0000] {taskinstance.py:1851} ERROR - Task failed with exception
Traceback (most recent call last):
  File "/home/airflow/.local/lib/python3.7/site-packages/airflow/operators/python.py", line 175, in execute
    return_value = self.execute_callable()
  File "/home/airflow/.local/lib/python3.7/site-packages/airflow/operators/python.py", line 193, in execute_callable
    return self.python_callable(*self.op_args, **self.op_kwargs)
  File "/opt/airflow/dags/data_ingestion_s3_dag.py", line 38, in upload_to_s3
    hook.load_file(filename=filename, key=key, bucket_name=bucket_name)
  File "/home/airflow/.local/lib/python3.7/site-packages/airflow/providers/amazon/aws/hooks/s3.py", line 64, in wrapper
    return func(*bound_args.args, **bound_args.kwargs)
  File "/home/airflow/.local/lib/python3.7/site-packages/airflow/providers/amazon/aws/hooks/s3.py", line 92, in wrapper
    return func(*bound_args.args, **bound_args.kwargs)
  File "/home/airflow/.local/lib/python3.7/site-packages/airflow/providers/amazon/aws/hooks/s3.py", line 633, in load_file
    if not replace and self.check_for_key(key, bucket_name):
  File "/home/airflow/.local/lib/python3.7/site-packages/airflow/providers/amazon/aws/hooks/s3.py", line 64, in wrapper
    return func(*bound_args.args, **bound_args.kwargs)
  File "/home/airflow/.local/lib/python3.7/site-packages/airflow/providers/amazon/aws/hooks/s3.py", line 92, in wrapper
    return func(*bound_args.args, **bound_args.kwargs)
  File "/home/airflow/.local/lib/python3.7/site-packages/airflow/providers/amazon/aws/hooks/s3.py", line 479, in check_for_key
    obj = self.head_object(key, bucket_name)
  File "/home/airflow/.local/lib/python3.7/site-packages/airflow/providers/amazon/aws/hooks/s3.py", line 64, in wrapper
    return func(*bound_args.args, **bound_args.kwargs)
  File "/home/airflow/.local/lib/python3.7/site-packages/airflow/providers/amazon/aws/hooks/s3.py", line 92, in wrapper
    return func(*bound_args.args, **bound_args.kwargs)
  File "/home/airflow/.local/lib/python3.7/site-packages/airflow/providers/amazon/aws/hooks/s3.py", line 466, in head_object
    raise e
  File "/home/airflow/.local/lib/python3.7/site-packages/airflow/providers/amazon/aws/hooks/s3.py", line 461, in head_object
    return self.get_conn().head_object(Bucket=bucket_name, Key=key)
  File "/home/airflow/.local/lib/python3.7/site-packages/botocore/client.py", line 515, in _api_call
    return self._make_api_call(operation_name, kwargs)
  File "/home/airflow/.local/lib/python3.7/site-packages/botocore/client.py", line 934, in _make_api_call
    raise error_class(parsed_response, operation_name)
botocore.exceptions.ClientError: An error occurred (403) when calling the HeadObject operation: Forbidden
[2022-11-26T09:34:16.410+0000] {taskinstance.py:1406} INFO - Marking task as FAILED. dag_id=data_ingestion_s3_dag, task_id=upload_to_s3, execution_date=20221126T092356, start_date=20221126T093412, end_date=20221126T093416
[2022-11-26T09:34:16.420+0000] {standard_task_runner.py:105} ERROR - Failed to execute job 98 for task upload_to_s3 (An error occurred (403) when calling the HeadObject operation: Forbidden; 747)
[2022-11-26T09:34:16.436+0000] {local_task_job.py:159} INFO - Task exited with return code 1
[2022-11-26T09:34:16.450+0000] {taskinstance.py:2623} INFO - 0 downstream tasks scheduled from follow-on schedule check
