[2022-11-22T16:56:26.501+0000] {taskinstance.py:1165} INFO - Dependencies all met for <TaskInstance: my_first_dag.weblog manual__2022-11-22T16:56:25.524190+00:00 [queued]>
[2022-11-22T16:56:26.510+0000] {taskinstance.py:1165} INFO - Dependencies all met for <TaskInstance: my_first_dag.weblog manual__2022-11-22T16:56:25.524190+00:00 [queued]>
[2022-11-22T16:56:26.511+0000] {taskinstance.py:1362} INFO - 
--------------------------------------------------------------------------------
[2022-11-22T16:56:26.512+0000] {taskinstance.py:1363} INFO - Starting attempt 1 of 3
[2022-11-22T16:56:26.513+0000] {taskinstance.py:1364} INFO - 
--------------------------------------------------------------------------------
[2022-11-22T16:56:26.522+0000] {taskinstance.py:1383} INFO - Executing <Task(PythonOperator): weblog> on 2022-11-22 16:56:25.524190+00:00
[2022-11-22T16:56:26.527+0000] {standard_task_runner.py:55} INFO - Started process 117 to run task
[2022-11-22T16:56:26.531+0000] {standard_task_runner.py:82} INFO - Running: ['***', 'tasks', 'run', 'my_first_dag', 'weblog', 'manual__2022-11-22T16:56:25.524190+00:00', '--job-id', '25', '--raw', '--subdir', 'DAGS_FOLDER/my_first_dag.py', '--cfg-path', '/tmp/tmpmx8v3gwd']
[2022-11-22T16:56:26.532+0000] {standard_task_runner.py:83} INFO - Job 25: Subtask weblog
[2022-11-22T16:56:26.580+0000] {task_command.py:376} INFO - Running <TaskInstance: my_first_dag.weblog manual__2022-11-22T16:56:25.524190+00:00 [running]> on host 317fffeda2ba
[2022-11-22T16:56:26.630+0000] {taskinstance.py:1592} INFO - Exporting the following env vars:
AIRFLOW_CTX_DAG_OWNER=***
AIRFLOW_CTX_DAG_ID=my_first_dag
AIRFLOW_CTX_TASK_ID=weblog
AIRFLOW_CTX_EXECUTION_DATE=2022-11-22T16:56:25.524190+00:00
AIRFLOW_CTX_TRY_NUMBER=1
AIRFLOW_CTX_DAG_RUN_ID=manual__2022-11-22T16:56:25.524190+00:00
[2022-11-22T16:56:26.632+0000] {taskinstance.py:1851} ERROR - Task failed with exception
Traceback (most recent call last):
  File "/home/airflow/.local/lib/python3.7/site-packages/airflow/operators/python.py", line 175, in execute
    return_value = self.execute_callable()
  File "/home/airflow/.local/lib/python3.7/site-packages/airflow/operators/python.py", line 193, in execute_callable
    return self.python_callable(*self.op_args, **self.op_kwargs)
  File "/opt/airflow/dags/my_first_dag.py", line 43, in f_generate_log
    logFile = generate_log(lines)
NameError: name 'generate_log' is not defined
[2022-11-22T16:56:26.641+0000] {taskinstance.py:1406} INFO - Marking task as UP_FOR_RETRY. dag_id=my_first_dag, task_id=weblog, execution_date=20221122T165625, start_date=20221122T165626, end_date=20221122T165626
[2022-11-22T16:56:26.651+0000] {standard_task_runner.py:105} ERROR - Failed to execute job 25 for task weblog (name 'generate_log' is not defined; 117)
[2022-11-22T16:56:26.663+0000] {local_task_job.py:159} INFO - Task exited with return code 1
[2022-11-22T16:56:26.688+0000] {taskinstance.py:2623} INFO - 0 downstream tasks scheduled from follow-on schedule check
