[2022-11-22T18:36:16.390+0000] {taskinstance.py:1165} INFO - Dependencies all met for <TaskInstance: my_first_dag.s3_upload_log_file manual__2022-11-22T18:36:13.089984+00:00 [queued]>
[2022-11-22T18:36:16.413+0000] {taskinstance.py:1165} INFO - Dependencies all met for <TaskInstance: my_first_dag.s3_upload_log_file manual__2022-11-22T18:36:13.089984+00:00 [queued]>
[2022-11-22T18:36:16.416+0000] {taskinstance.py:1362} INFO - 
--------------------------------------------------------------------------------
[2022-11-22T18:36:16.423+0000] {taskinstance.py:1363} INFO - Starting attempt 1 of 3
[2022-11-22T18:36:16.431+0000] {taskinstance.py:1364} INFO - 
--------------------------------------------------------------------------------
[2022-11-22T18:36:16.470+0000] {taskinstance.py:1383} INFO - Executing <Task(PythonOperator): s3_upload_log_file> on 2022-11-22 18:36:13.089984+00:00
[2022-11-22T18:36:16.486+0000] {standard_task_runner.py:55} INFO - Started process 81 to run task
[2022-11-22T18:36:16.492+0000] {standard_task_runner.py:82} INFO - Running: ['***', 'tasks', 'run', 'my_first_dag', 's3_upload_log_file', 'manual__2022-11-22T18:36:13.089984+00:00', '--job-id', '43', '--raw', '--subdir', 'DAGS_FOLDER/my_first_dag.py', '--cfg-path', '/tmp/tmp794z4k3y']
[2022-11-22T18:36:16.502+0000] {standard_task_runner.py:83} INFO - Job 43: Subtask s3_upload_log_file
[2022-11-22T18:36:16.655+0000] {task_command.py:376} INFO - Running <TaskInstance: my_first_dag.s3_upload_log_file manual__2022-11-22T18:36:13.089984+00:00 [running]> on host abf9e0bd4989
[2022-11-22T18:36:16.760+0000] {taskinstance.py:1592} INFO - Exporting the following env vars:
AIRFLOW_CTX_DAG_OWNER=***
AIRFLOW_CTX_DAG_ID=my_first_dag
AIRFLOW_CTX_TASK_ID=s3_upload_log_file
AIRFLOW_CTX_EXECUTION_DATE=2022-11-22T18:36:13.089984+00:00
AIRFLOW_CTX_TRY_NUMBER=1
AIRFLOW_CTX_DAG_RUN_ID=manual__2022-11-22T18:36:13.089984+00:00
[2022-11-22T18:36:18.984+0000] {taskinstance.py:1851} ERROR - Task failed with exception
Traceback (most recent call last):
  File "/home/airflow/.local/lib/python3.7/site-packages/airflow/operators/python.py", line 175, in execute
    return_value = self.execute_callable()
  File "/home/airflow/.local/lib/python3.7/site-packages/airflow/operators/python.py", line 193, in execute_callable
    return self.python_callable(*self.op_args, **self.op_kwargs)
  File "/opt/airflow/dags/my_first_dag.py", line 56, in s3_upload_file
    response = s3_client.upload_file(fileName, bucketName, objectName)
  File "/home/airflow/.local/lib/python3.7/site-packages/boto3/s3/inject.py", line 148, in upload_file
    callback=Callback,
  File "/home/airflow/.local/lib/python3.7/site-packages/boto3/s3/transfer.py", line 288, in upload_file
    future.result()
  File "/home/airflow/.local/lib/python3.7/site-packages/s3transfer/futures.py", line 103, in result
    return self._coordinator.result()
  File "/home/airflow/.local/lib/python3.7/site-packages/s3transfer/futures.py", line 266, in result
    raise self._exception
  File "/home/airflow/.local/lib/python3.7/site-packages/s3transfer/tasks.py", line 139, in __call__
    return self._execute_main(kwargs)
  File "/home/airflow/.local/lib/python3.7/site-packages/s3transfer/tasks.py", line 162, in _execute_main
    return_value = self._main(**kwargs)
  File "/home/airflow/.local/lib/python3.7/site-packages/s3transfer/upload.py", line 758, in _main
    client.put_object(Bucket=bucket, Key=key, Body=body, **extra_args)
  File "/home/airflow/.local/lib/python3.7/site-packages/botocore/client.py", line 515, in _api_call
    return self._make_api_call(operation_name, kwargs)
  File "/home/airflow/.local/lib/python3.7/site-packages/botocore/client.py", line 918, in _make_api_call
    operation_model, request_dict, request_context
  File "/home/airflow/.local/lib/python3.7/site-packages/botocore/client.py", line 940, in _make_request
    return self._endpoint.make_request(operation_model, request_dict)
  File "/home/airflow/.local/lib/python3.7/site-packages/botocore/endpoint.py", line 119, in make_request
    return self._send_request(request_dict, operation_model)
  File "/home/airflow/.local/lib/python3.7/site-packages/botocore/endpoint.py", line 198, in _send_request
    request = self.create_request(request_dict, operation_model)
  File "/home/airflow/.local/lib/python3.7/site-packages/botocore/endpoint.py", line 137, in create_request
    operation_name=operation_model.name,
  File "/home/airflow/.local/lib/python3.7/site-packages/botocore/hooks.py", line 412, in emit
    return self._emitter.emit(aliased_event_name, **kwargs)
  File "/home/airflow/.local/lib/python3.7/site-packages/botocore/hooks.py", line 256, in emit
    return self._emit(event_name, kwargs)
  File "/home/airflow/.local/lib/python3.7/site-packages/botocore/hooks.py", line 239, in _emit
    response = handler(**kwargs)
  File "/home/airflow/.local/lib/python3.7/site-packages/botocore/signers.py", line 105, in handler
    return self.sign(operation_name, request)
  File "/home/airflow/.local/lib/python3.7/site-packages/botocore/signers.py", line 189, in sign
    auth.add_auth(request)
  File "/home/airflow/.local/lib/python3.7/site-packages/botocore/auth.py", line 418, in add_auth
    raise NoCredentialsError()
botocore.exceptions.NoCredentialsError: Unable to locate credentials
[2022-11-22T18:36:18.998+0000] {taskinstance.py:1406} INFO - Marking task as UP_FOR_RETRY. dag_id=my_first_dag, task_id=s3_upload_log_file, execution_date=20221122T183613, start_date=20221122T183616, end_date=20221122T183618
[2022-11-22T18:36:19.020+0000] {standard_task_runner.py:105} ERROR - Failed to execute job 43 for task s3_upload_log_file (Unable to locate credentials; 81)
[2022-11-22T18:36:19.055+0000] {local_task_job.py:159} INFO - Task exited with return code 1
[2022-11-22T18:36:19.079+0000] {taskinstance.py:2623} INFO - 0 downstream tasks scheduled from follow-on schedule check
