[2022-11-25T20:34:02.076+0000] {taskinstance.py:1165} INFO - Dependencies all met for <TaskInstance: my_first_dag.s3_upload_log_file manual__2022-11-22T18:36:13.089984+00:00 [queued]>
[2022-11-25T20:34:02.083+0000] {taskinstance.py:1165} INFO - Dependencies all met for <TaskInstance: my_first_dag.s3_upload_log_file manual__2022-11-22T18:36:13.089984+00:00 [queued]>
[2022-11-25T20:34:02.084+0000] {taskinstance.py:1362} INFO - 
--------------------------------------------------------------------------------
[2022-11-25T20:34:02.085+0000] {taskinstance.py:1363} INFO - Starting attempt 3 of 3
[2022-11-25T20:34:02.086+0000] {taskinstance.py:1364} INFO - 
--------------------------------------------------------------------------------
[2022-11-25T20:34:02.093+0000] {taskinstance.py:1383} INFO - Executing <Task(PythonOperator): s3_upload_log_file> on 2022-11-22 18:36:13.089984+00:00
[2022-11-25T20:34:02.097+0000] {standard_task_runner.py:55} INFO - Started process 310 to run task
[2022-11-25T20:34:02.100+0000] {standard_task_runner.py:82} INFO - Running: ['***', 'tasks', 'run', 'my_first_dag', 's3_upload_log_file', 'manual__2022-11-22T18:36:13.089984+00:00', '--job-id', '86', '--raw', '--subdir', 'DAGS_FOLDER/my_first_dag.py', '--cfg-path', '/tmp/tmpgonay69k']
[2022-11-25T20:34:02.101+0000] {standard_task_runner.py:83} INFO - Job 86: Subtask s3_upload_log_file
[2022-11-25T20:34:02.139+0000] {task_command.py:376} INFO - Running <TaskInstance: my_first_dag.s3_upload_log_file manual__2022-11-22T18:36:13.089984+00:00 [running]> on host 2d375264ca65
[2022-11-25T20:34:02.177+0000] {taskinstance.py:1592} INFO - Exporting the following env vars:
AIRFLOW_CTX_DAG_OWNER=***
AIRFLOW_CTX_DAG_ID=my_first_dag
AIRFLOW_CTX_TASK_ID=s3_upload_log_file
AIRFLOW_CTX_EXECUTION_DATE=2022-11-22T18:36:13.089984+00:00
AIRFLOW_CTX_TRY_NUMBER=3
AIRFLOW_CTX_DAG_RUN_ID=manual__2022-11-22T18:36:13.089984+00:00
[2022-11-25T20:34:02.193+0000] {credentials.py:1180} INFO - Found credentials in environment variables.
[2022-11-25T20:34:02.241+0000] {taskinstance.py:1851} ERROR - Task failed with exception
Traceback (most recent call last):
  File "/home/airflow/.local/lib/python3.7/site-packages/airflow/operators/python.py", line 175, in execute
    return_value = self.execute_callable()
  File "/home/airflow/.local/lib/python3.7/site-packages/airflow/operators/python.py", line 193, in execute_callable
    return self.python_callable(*self.op_args, **self.op_kwargs)
  File "/opt/airflow/dags/my_first_dag.py", line 56, in s3_upload_file
    response = s3_client.upload_file(fileName, bucketName, objectName)
  File "/home/airflow/.local/lib/python3.7/site-packages/boto3/s3/inject.py", line 148, in upload_file
    callback=Callback,
  File "/home/airflow/.local/lib/python3.7/site-packages/boto3/s3/transfer.py", line 288, in upload_file
    future.result()
  File "/home/airflow/.local/lib/python3.7/site-packages/s3transfer/futures.py", line 103, in result
    return self._coordinator.result()
  File "/home/airflow/.local/lib/python3.7/site-packages/s3transfer/futures.py", line 266, in result
    raise self._exception
  File "/home/airflow/.local/lib/python3.7/site-packages/s3transfer/tasks.py", line 269, in _main
    self._submit(transfer_future=transfer_future, **kwargs)
  File "/home/airflow/.local/lib/python3.7/site-packages/s3transfer/upload.py", line 585, in _submit
    upload_input_manager.provide_transfer_size(transfer_future)
  File "/home/airflow/.local/lib/python3.7/site-packages/s3transfer/upload.py", line 244, in provide_transfer_size
    self._osutil.get_file_size(transfer_future.meta.call_args.fileobj)
  File "/home/airflow/.local/lib/python3.7/site-packages/s3transfer/utils.py", line 247, in get_file_size
    return os.path.getsize(filename)
  File "/usr/local/lib/python3.7/genericpath.py", line 50, in getsize
    return os.stat(filename).st_size
FileNotFoundError: [Errno 2] No such file or directory: 'weblog_20221122-183615.log'
[2022-11-25T20:34:02.250+0000] {taskinstance.py:1406} INFO - Marking task as FAILED. dag_id=my_first_dag, task_id=s3_upload_log_file, execution_date=20221122T183613, start_date=20221125T203402, end_date=20221125T203402
[2022-11-25T20:34:02.258+0000] {standard_task_runner.py:105} ERROR - Failed to execute job 86 for task s3_upload_log_file ([Errno 2] No such file or directory: 'weblog_20221122-183615.log'; 310)
[2022-11-25T20:34:02.272+0000] {local_task_job.py:159} INFO - Task exited with return code 1
[2022-11-25T20:34:02.284+0000] {taskinstance.py:2623} INFO - 0 downstream tasks scheduled from follow-on schedule check
