[2022-11-22T16:43:40.572+0000] {taskinstance.py:1165} INFO - Dependencies all met for <TaskInstance: my_first_dag.weblog manual__2022-11-22T16:40:00.987526+00:00 [queued]>
[2022-11-22T16:43:40.579+0000] {taskinstance.py:1165} INFO - Dependencies all met for <TaskInstance: my_first_dag.weblog manual__2022-11-22T16:40:00.987526+00:00 [queued]>
[2022-11-22T16:43:40.580+0000] {taskinstance.py:1362} INFO - 
--------------------------------------------------------------------------------
[2022-11-22T16:43:40.584+0000] {taskinstance.py:1363} INFO - Starting attempt 2 of 4
[2022-11-22T16:43:40.585+0000] {taskinstance.py:1364} INFO - 
--------------------------------------------------------------------------------
[2022-11-22T16:43:40.593+0000] {taskinstance.py:1383} INFO - Executing <Task(PythonOperator): weblog> on 2022-11-22 16:40:00.987526+00:00
[2022-11-22T16:43:40.597+0000] {standard_task_runner.py:55} INFO - Started process 737 to run task
[2022-11-22T16:43:40.600+0000] {standard_task_runner.py:82} INFO - Running: ['***', 'tasks', 'run', 'my_first_dag', 'weblog', 'manual__2022-11-22T16:40:00.987526+00:00', '--job-id', '17', '--raw', '--subdir', 'DAGS_FOLDER/my_first_dag.py', '--cfg-path', '/tmp/tmpo7xvnff8']
[2022-11-22T16:43:40.601+0000] {standard_task_runner.py:83} INFO - Job 17: Subtask weblog
[2022-11-22T16:43:40.653+0000] {task_command.py:376} INFO - Running <TaskInstance: my_first_dag.weblog manual__2022-11-22T16:40:00.987526+00:00 [running]> on host 8bacb641eea1
[2022-11-22T16:43:40.699+0000] {taskinstance.py:1592} INFO - Exporting the following env vars:
AIRFLOW_CTX_DAG_OWNER=***
AIRFLOW_CTX_DAG_ID=my_first_dag
AIRFLOW_CTX_TASK_ID=weblog
AIRFLOW_CTX_EXECUTION_DATE=2022-11-22T16:40:00.987526+00:00
AIRFLOW_CTX_TRY_NUMBER=2
AIRFLOW_CTX_DAG_RUN_ID=manual__2022-11-22T16:40:00.987526+00:00
[2022-11-22T16:43:40.701+0000] {taskinstance.py:1851} ERROR - Task failed with exception
Traceback (most recent call last):
  File "/home/airflow/.local/lib/python3.7/site-packages/airflow/operators/python.py", line 175, in execute
    return_value = self.execute_callable()
  File "/home/airflow/.local/lib/python3.7/site-packages/airflow/operators/python.py", line 193, in execute_callable
    return self.python_callable(*self.op_args, **self.op_kwargs)
  File "/opt/airflow/dags/my_first_dag.py", line 43, in f_generate_log
    logFile = generate_log(lines)
NameError: name 'generate_log' is not defined
[2022-11-22T16:43:40.709+0000] {taskinstance.py:1406} INFO - Marking task as UP_FOR_RETRY. dag_id=my_first_dag, task_id=weblog, execution_date=20221122T164000, start_date=20221122T164340, end_date=20221122T164340
[2022-11-22T16:43:40.716+0000] {standard_task_runner.py:105} ERROR - Failed to execute job 17 for task weblog (name 'generate_log' is not defined; 737)
[2022-11-22T16:43:40.733+0000] {local_task_job.py:159} INFO - Task exited with return code 1
[2022-11-22T16:43:40.749+0000] {taskinstance.py:2623} INFO - 0 downstream tasks scheduled from follow-on schedule check
