[2022-11-26T09:47:39.308+0000] {taskinstance.py:1165} INFO - Dependencies all met for <TaskInstance: data_ingestion_s3_dag.upload_to_s3 manual__2022-11-26T09:47:34.066447+00:00 [queued]>
[2022-11-26T09:47:39.314+0000] {taskinstance.py:1165} INFO - Dependencies all met for <TaskInstance: data_ingestion_s3_dag.upload_to_s3 manual__2022-11-26T09:47:34.066447+00:00 [queued]>
[2022-11-26T09:47:39.315+0000] {taskinstance.py:1362} INFO - 
--------------------------------------------------------------------------------
[2022-11-26T09:47:39.316+0000] {taskinstance.py:1363} INFO - Starting attempt 1 of 2
[2022-11-26T09:47:39.316+0000] {taskinstance.py:1364} INFO - 
--------------------------------------------------------------------------------
[2022-11-26T09:47:39.329+0000] {taskinstance.py:1383} INFO - Executing <Task(PythonOperator): upload_to_s3> on 2022-11-26 09:47:34.066447+00:00
[2022-11-26T09:47:39.334+0000] {standard_task_runner.py:55} INFO - Started process 1453 to run task
[2022-11-26T09:47:39.336+0000] {standard_task_runner.py:82} INFO - Running: ['***', 'tasks', 'run', 'data_ingestion_s3_dag', 'upload_to_s3', 'manual__2022-11-26T09:47:34.066447+00:00', '--job-id', '104', '--raw', '--subdir', 'DAGS_FOLDER/data_ingestion_s3_dag.py', '--cfg-path', '/tmp/tmps1oabmoe']
[2022-11-26T09:47:39.338+0000] {standard_task_runner.py:83} INFO - Job 104: Subtask upload_to_s3
[2022-11-26T09:47:39.377+0000] {task_command.py:376} INFO - Running <TaskInstance: data_ingestion_s3_dag.upload_to_s3 manual__2022-11-26T09:47:34.066447+00:00 [running]> on host 7d1b5368210b
[2022-11-26T09:47:39.417+0000] {taskinstance.py:1592} INFO - Exporting the following env vars:
AIRFLOW_CTX_DAG_OWNER=***
AIRFLOW_CTX_DAG_ID=data_ingestion_s3_dag
AIRFLOW_CTX_TASK_ID=upload_to_s3
AIRFLOW_CTX_EXECUTION_DATE=2022-11-26T09:47:34.066447+00:00
AIRFLOW_CTX_TRY_NUMBER=1
AIRFLOW_CTX_DAG_RUN_ID=manual__2022-11-26T09:47:34.066447+00:00
[2022-11-26T09:47:39.424+0000] {base_aws.py:120} INFO - No connection ID provided. Fallback on boto3 credential strategy (region_name=None). See: https://boto3.amazonaws.com/v1/documentation/api/latest/guide/configuration.html
[2022-11-26T09:47:39.432+0000] {credentials.py:1180} INFO - Found credentials in environment variables.
[2022-11-26T09:47:43.178+0000] {taskinstance.py:1851} ERROR - Task failed with exception
Traceback (most recent call last):
  File "/home/airflow/.local/lib/python3.7/site-packages/airflow/operators/python.py", line 175, in execute
    return_value = self.execute_callable()
  File "/home/airflow/.local/lib/python3.7/site-packages/airflow/operators/python.py", line 193, in execute_callable
    return self.python_callable(*self.op_args, **self.op_kwargs)
  File "/opt/airflow/dags/data_ingestion_s3_dag.py", line 38, in upload_to_s3
    hook.load_file(filename=filename, key=key, bucket_name=bucket_name)
  File "/home/airflow/.local/lib/python3.7/site-packages/airflow/providers/amazon/aws/hooks/s3.py", line 64, in wrapper
    return func(*bound_args.args, **bound_args.kwargs)
  File "/home/airflow/.local/lib/python3.7/site-packages/airflow/providers/amazon/aws/hooks/s3.py", line 92, in wrapper
    return func(*bound_args.args, **bound_args.kwargs)
  File "/home/airflow/.local/lib/python3.7/site-packages/airflow/providers/amazon/aws/hooks/s3.py", line 634, in load_file
    raise ValueError(f"The key {key} already exists.")
ValueError: The key new_york_data already exists.
[2022-11-26T09:47:43.188+0000] {taskinstance.py:1406} INFO - Marking task as UP_FOR_RETRY. dag_id=data_ingestion_s3_dag, task_id=upload_to_s3, execution_date=20221126T094734, start_date=20221126T094739, end_date=20221126T094743
[2022-11-26T09:47:43.198+0000] {standard_task_runner.py:105} ERROR - Failed to execute job 104 for task upload_to_s3 (The key new_york_data already exists.; 1453)
[2022-11-26T09:47:43.238+0000] {local_task_job.py:159} INFO - Task exited with return code 1
[2022-11-26T09:47:43.253+0000] {taskinstance.py:2623} INFO - 0 downstream tasks scheduled from follow-on schedule check
